<?xml version="1.0" ?>
<robot name="storagy" xmlns:xacro="http://ros.org/wiki/xacro">
  <!-- <xacro:include filename="$(find storagy)/urdf/common_properties.urdf"/> -->

  <!-- Init colour -->
  <material name="black">
      <color rgba="0.0 0.0 0.0 1.0"/>
  </material>

  <material name="dark">
    <color rgba="0.3 0.3 0.3 1.0"/>
  </material>

  <material name="light_black">
    <color rgba="0.4 0.4 0.4 1.0"/>
  </material>

  <material name="blue">
    <color rgba="0.0 0.0 0.8 1.0"/>
  </material>

  <material name="green">
    <color rgba="0.0 0.8 0.0 1.0"/>
  </material>

  <material name="grey">
    <color rgba="0.5 0.5 0.5 1.0"/>
  </material>

  <material name="orange">
    <color rgba="1.0 0.4235 0.0392 1.0"/>
  </material>

  <material name="brown">
    <color rgba="0.8706 0.8118 0.7647 1.0"/>
  </material>

  <material name="red">
    <color rgba="0.8 0.0 0.0 1.0"/>
  </material>

  <material name="white">
    <color rgba="1.0 1.0 1.0 1.0"/>
  </material>

  <link name="base_footprint"/>

  <joint name="base_joint" type="fixed">
    <parent link="base_footprint"/>
    <child link="base_link" />
    <origin xyz="0 0 0.065" rpy="0 0 0"/>
  </joint>

  <link name="base_link">
    <visual>
      <origin xyz="0.0 0 0.13" rpy="0 0 0"/>
      <geometry>
        <!-- <mesh filename="package://storagy/meshes/bases/Main.stl" scale="0.01 0.01 0.01"/> -->
        <box size="0.4 0.3 0.26"/>
      </geometry>
      <material name="white"/>
    </visual>

    <collision>
      <origin xyz="-0.064 0 0.047" rpy="0 0 0"/>
      <geometry>
        <box size="0.266 0.266 0.094"/>
      </geometry>
    </collision>

    <inertial>
      <origin xyz="0 0 0" rpy="0 0 0"/>
      <mass value="1.3729096e+00"/>
      <inertia ixx="8.7002718e-03" ixy="-4.7576583e-05" ixz="1.1160499e-04"
               iyy="8.6195418e-03" iyz="-3.5422299e-06"
               izz="1.4612727e-02" />
    </inertial>
  </link>

  <joint name="wheel_front_left_joint" type="continuous">
    <parent link="base_link"/>
    <child link="wheel_front_left_link"/>
    <origin xyz="0.0 0.1 0.0" rpy="0 0 0"/>
    <axis xyz="0 1 0"/>
  </joint>

  <link name="wheel_front_left_link">
    <visual>
      <origin xyz="0 0 0" rpy="-1.57 0 0.0"/>
      <geometry>
        <!-- <mesh filename="package://storagy/meshes/wheels/Front_left_wheel.stl" scale="0.01 0.01 0.01"/> -->
        <cylinder length="0.08" radius="0.065"/>
      </geometry>
      <material name="dark"/>
    </visual>

    <collision>
      <origin xyz="0 0 0" rpy="0 0 0"/>
      <geometry>
        <cylinder length="0.018" radius="0.033"/>
      </geometry>
    </collision>

    <inertial>
      <origin xyz="0 0 0" />
      <mass value="2.8498940e-02" />
      <inertia ixx="1.1175580e-05" ixy="-4.2369783e-11" ixz="-5.9381719e-09"
               iyy="1.1192413e-05" iyz="-1.4400107e-11"
               izz="2.0712558e-05" />
      </inertial>
  </link>

  <joint name="wheel_front_right_joint" type="continuous">
    <parent link="base_link"/>
    <child link="wheel_front_right_link"/>
    <origin xyz="0.0 -0.1 0.0" rpy="0 0 0"/>
    <axis xyz="0 1 0"/>
  </joint>

  <link name="wheel_front_right_link">
    <visual>
      <origin xyz="0 0 0" rpy="-1.57 0 0"/>
      <geometry>
        <!-- <mesh filename="package://storagy/meshes/wheels/Front_right_wheel.stl" scale="0.01 0.01 0.01"/> -->
        <cylinder length="0.08" radius="0.065"/>
      </geometry>
      <material name="dark"/>
    </visual>

    <collision>
      <origin xyz="0 0 0" rpy="0 0 0"/>
      <geometry>
        <cylinder length="0.018" radius="0.033"/>
      </geometry>
    </collision>

    <inertial>
      <origin xyz="0 0 0" />
      <mass value="2.8498940e-02" />
      <inertia ixx="1.1175580e-05" ixy="-4.2369783e-11" ixz="-5.9381719e-09"
               iyy="1.1192413e-05" iyz="-1.4400107e-11"
               izz="2.0712558e-05" />
      </inertial>
  </link>

  <joint name="imu_joint" type="fixed">
    <parent link="base_link"/>
    <child link="imu_link"/>
    <origin xyz="0.0 0 0.068" rpy="0 0 0"/>
  </joint>

  <link name="imu_link"/>

  <joint name="front_scan_joint" type="fixed">
    <parent link="base_link"/>
    <child link="front_base_scan"/>
    <origin xyz="0.1525 0.0 0.062" rpy="3.142857143 0 0"/>
  </joint>

  <link name="front_base_scan">
    <visual>
      <origin xyz="0 0 0.0" rpy="0 0 0"/>
      <geometry>
        <mesh filename="package://storagy/meshes/sensors/lidar.stl" scale="0.01 0.01 0.01"/>
      </geometry>
      <material name="dark"/>
    </visual>

    <collision>
      <origin xyz="0.015 0 -0.0065" rpy="0 0 0"/>
      <geometry>
        <cylinder length="0.0315" radius="0.055"/>
      </geometry>
    </collision>

    <inertial>
      <mass value="0.114" />
      <origin xyz="0 0 0" />
      <inertia ixx="0.001" ixy="0.0" ixz="0.0"
               iyy="0.001" iyz="0.0"
               izz="0.001" />
    </inertial>
  </link>

  <joint name="camera_joint" type="fixed">
    <origin xyz="0.198 0.0 0.2295" rpy="0 0 0"/>
    <parent link="base_link"/>
    <child link="camera_link"/>
  </joint>

  <link name="camera_link">
    <visual>
      <origin xyz="0.0 0.0 0.0" rpy="0 0 0"/>
      <geometry>
        <mesh filename="package://storagy/meshes/sensors/camera.stl" scale="0.01 0.01 0.01"/>
      </geometry>
      <material name="light_black"/>
    </visual>
    <collision>
      <origin xyz="0.0 0.0 0.0" rpy="0 0 0"/>
      <geometry>
        <mesh filename="package://storagy/meshes/sensors/camera.stl" scale="0.01 0.01 0.01"/>
      </geometry>
    </collision>
  </link>

  <joint name="camera_rgb_joint" type="fixed">
    <!-- <origin xyz="0.003 0.011 0.009" rpy="3.14 0 0"/> -->
    <origin xyz="0 0 0" rpy="0 0 0"/>
    <parent link="camera_link"/>
    <child link="camera_rgb_frame"/>
  </joint>
  <link name="camera_rgb_frame"/>

  <joint name="camera_rgb_optical_joint" type="fixed">
    <origin xyz="0 0 0" rpy="-1.57 0 -1.57"/>
    <parent link="camera_rgb_frame"/>
    <child link="camera_color_optical_frame"/>
  </joint>
  <link name="camera_color_optical_frame"/>

  <gazebo>
    <plugin name="storagy_diff_drive" filename="libgazebo_ros_diff_drive.so">
      <ros>
        <namespace>/</namespace>
        <remapping>cmd_vel:=cmd_vel</remapping>
        <remapping>odom:=odom</remapping>
      </ros>
      <left_joint>wheel_front_left_joint</left_joint>
      <right_joint>wheel_front_right_joint</right_joint>
      <wheel_separation>0.2</wheel_separation>
      <wheel_diameter>0.13</wheel_diameter>
      <max_wheel_torque>20</max_wheel_torque>
      <max_wheel_acceleration>1.0</max_wheel_acceleration>
      <publish_odom>true</publish_odom>
      <publish_odom_tf>true</publish_odom_tf>
      <publish_wheel_tf>false</publish_wheel_tf>
      <odometry_frame>odom</odometry_frame>
      <robot_base_frame>base_footprint</robot_base_frame>
    </plugin>
  </gazebo>

  <gazebo reference="front_base_scan">
    <sensor type="ray" name="front_lidar">
      <pose>0 0 0 0 0 0</pose>
      <visualize>true</visualize>
      <update_rate>15</update_rate>
      <ray>
        <scan>
          <horizontal>
            <samples>360</samples>
            <resolution>1</resolution>
            <min_angle>-3.141592</min_angle>
            <max_angle>3.141592</max_angle>
          </horizontal>
        </scan>
        <range>
          <min>0.12</min>
          <max>10.0</max>
          <resolution>0.01</resolution>
        </range>
      </ray>
      <plugin name="storagy_laserscan" filename="libgazebo_ros_ray_sensor.so">
        <ros>
          <namespace>/</namespace>
          <remapping>~/out:=scan</remapping>
        </ros>
        <output_type>sensor_msgs/LaserScan</output_type>
        <frame_name>front_base_scan</frame_name>
      </plugin>
    </sensor>
  </gazebo>

</robot>
